<?xml version="1.0"?>
<robot xmlns:xacro="http://ros.org/wiki/xacro">

  <xacro:include filename="$(find auto_car)/urdf/wheel/wheel.transmission.xacro"/>
  <xacro:include filename="$(find auto_car)/urdf/wheel/wheel.gazebo.xacro"/>
  
  <xacro:macro name="wheel_lr_v0" params="prefix parent *joint_origin *joint_axis">
	<joint name="${prefix}_wheel_joint" type="continuous">
	  <xacro:insert_block name="joint_origin"/>
	  <parent link="${parent}"/>
	  <child link="${prefix}_wheel_link"/>
         <limit effort="100" velocity="20"/>
	  <xacro:insert_block name="joint_axis"/>
	</joint>

	<link name="${prefix}_wheel_link">
	<inertial>
      <origin
        xyz="1.0538E-05 -0.014796 -5.4972E-05"
        rpy="0 0 0" />
      <mass
        value="0.22482" />
      <inertia
        ixx="0.0001051"
        ixy="-1.0031E-08"
        ixz="5.6889E-08"
        iyy="0.00018754"
        iyz="9.9276E-10"
        izz="0.00010567" />
    </inertial>
    <visual>
      <origin
        xyz="0 0 0"
        rpy="0 0 0" />
      <geometry>
        <mesh
          filename="package://auto_car/meshes/lr_wheel_link.STL" />
      </geometry>
      <material
        name="">
        <color
          rgba="1 1 1 1" />
      </material>
    </visual>
    <collision>
      <origin
        xyz="0 0 0"
        rpy="0 0 0" />
      <geometry>
        <mesh
          filename="package://auto_car/meshes/lr_wheel_link.STL" />
      </geometry>
    </collision>
	</link>
  </xacro:macro>
  
</robot>

